<?xml version="1.0" encoding="utf-8"?>
<!-- This URDF was automatically created by SolidWorks to URDF Exporter! Originally created by Stephen Brawner (brawner@gmail.com) 
     Commit Version: 1.6.0-4-g7f85cfe  Build Version: 1.6.7995.38578
     For more information, please see http://wiki.ros.org/sw_urdf_exporter -->
<robot xmlns:xacro="http://www.ros.org/wiki/xacro">
  <xacro:property name="mesh_dir" value="$(find demeter_description)/models/meshes" />
  <link
    name="base_link">
    <inertial>
      <origin
        xyz="-0.146665450570513 -0.130801224430533 0.104522386184565"
        rpy="0 0 0" />
      <mass
        value="500.894708923615" />
      <inertia
        ixx="18.4023004638644"
        ixy="-0.00177025285701215"
        ixz="1.11260688454139"
        iyy="44.5321575820338"
        iyz="0.0635919234687216"
        izz="48.9707086072726" />
    </inertial>
    <visual>
      <origin
        xyz="0 0 0"
        rpy="0 0 0" />
      <geometry>
        <mesh
          filename="file://${mesh_dir}/base_link.STL" />
      </geometry>
      <material
        name="">
        <color
          rgba="0.901960784313726 0.92156862745098 0.92156862745098 1" />
      </material>
    </visual>
    <collision>
      <origin
        xyz="0 0 0.3"
        rpy="0 0 0" />
      <geometry>
        <box size="1.9 1.0 0.7"/> <!-- длина/ширина/высота корпуса -->
      </geometry>
    </collision>
  </link>

  <link name="imu_link"/>
  <link name="navsat_link"/>
  <link name="front_cams"/>
  <link name="left_cams"/>
  <link name="right_cams"/>
  <!-- Front cameras -->
  <link name="front_left_camera">
    <visual>
      <geometry>
        <box size="0.01 0.01 0.01"/>
      </geometry>
    </visual>
  </link>
  <link name="front_right_camera">
    <visual>
      <geometry>
        <box size="0.01 0.01 0.01"/>
      </geometry>
    </visual>
  </link>

  <!-- Left cameras -->
  <link name="left_front_camera">
    <visual>
      <geometry>
        <box size="0.01 0.01 0.01"/>
      </geometry>
    </visual>
  </link>
  <link name="left_back_camera">
    <visual>
      <geometry>
        <box size="0.01 0.01 0.01"/>
      </geometry>
    </visual>
  </link>

  <!-- Right cameras -->
  <link name="right_front_camera">
    <visual>
      <geometry>
        <box size="0.01 0.01 0.01"/>
      </geometry>
    </visual>
  </link>
  <link name="right_back_camera">
    <visual>
      <geometry>
        <box size="0.01 0.01 0.01"/>
      </geometry>
    </visual>
  </link>
  <joint name="imu_joint" type="fixed">
    <origin xyz="0 0 0" rpy="0 0 0"/>
    <parent link="base_link"/>
    <child link="imu_link"/>
  </joint>

  <joint name="navsat_joint" type="fixed">
    <origin xyz="0 0 0.2" rpy="0 0 0"/>
    <parent link="base_link"/>
    <child link="navsat_link"/>
  </joint>
  <!-- Joints для позиционирования камер -->
  <joint name="base_to_front_cams" type="fixed">
    <parent link="base_link"/>
    <child link="front_cams"/>
    <origin xyz="1.2 0.0 0.1" rpy="0 0 0"/> <!-- центр между камерами -->
  </joint>
  <joint name="base_to_left_cams" type="fixed">
    <parent link="base_link"/>
    <child link="left_cams"/>
    <origin xyz="0.4125 0.52 0.1" rpy="0 0 1.5708"/> <!-- центр между камерами -->
  </joint>
  <joint name="base_to_right_cams" type="fixed">
    <parent link="base_link"/>
    <child link="right_cams"/>
    <origin xyz="0.4125 -0.52 0.1" rpy="0 0 -1.5708"/> <!-- центр между камерами -->
  </joint>

  <joint name="base_to_front_left_camera" type="fixed">
    <parent link="front_cams"/>
    <child link="front_left_camera"/>
    <origin xyz="0 0.0375 0" rpy="0 0 0"/>
  </joint>
  <joint name="base_to_front_right_camera" type="fixed">
    <parent link="front_cams"/>
    <child link="front_right_camera"/>
    <origin xyz="0 -0.0375 0" rpy="0 0 0"/>
  </joint>
  <joint name="base_to_left_front_camera" type="fixed">
    <parent link="left_cams"/>
    <child link="left_front_camera"/>
    <origin xyz="0 0.0375 0" rpy="0 0 0"/>
  </joint>
  <joint name="base_to_left_back_camera" type="fixed">
    <parent link="left_cams"/>
    <child link="left_back_camera"/>
    <origin xyz="0 -0.0375 0" rpy="0 0 0"/>
  </joint>
  <joint name="base_to_right_front_camera" type="fixed">
    <parent link="right_cams"/>
    <child link="right_front_camera"/>
    <origin xyz="0 -0.0375 0" rpy="0 0 0"/>
  </joint>
  <joint name="base_to_right_back_camera" type="fixed">
    <parent link="right_cams"/>
    <child link="right_back_camera"/>
    <origin xyz="0 0.0375 0" rpy="0 0 0"/>
  </joint>

  <link
    name="Link1">
    <inertial>
      <origin
        xyz="-0.000625241762713614 -0.0350031471656116 -0.153698690860985"
        rpy="0 0 0" />
      <mass
        value="50.3713170440083" />
      <inertia
        ixx="0.300649617343705"
        ixy="0.0012819508517115"
        ixz="-0.00185277975719995"
        iyy="0.508223841043124"
        iyz="-3.92492744232425E-05"
        izz="0.246871602311289" />
    </inertial>
    <visual>
      <origin
        xyz="0 0 0"
        rpy="0 0 0" />
      <geometry>
        <mesh
          filename="file://${mesh_dir}/Link1.STL" />
      </geometry>
      <material
        name="">
        <color
          rgba="0.901960784313726 0.92156862745098 0.92156862745098 1" />
      </material>
    </visual>
    <collision>
      <origin
        xyz="0 0 0"
        rpy="0 0 0" />
      <geometry>
        <mesh
          filename="file://${mesh_dir}/Link1.STL" />
      </geometry>
    </collision>
  </link>
  <joint
    name="Right_absorber"
    type="fixed">
    <origin
      xyz="0.0480168574191399 -0.305000000000022 -0.229644819222496"
      rpy="0 0 0" />
    <parent
      link="base_link" />
    <child
      link="Link1" />
    <axis
      xyz="0 0 0" />
  </joint>
  <link
    name="Link1.1">
    <inertial>
      <origin
        xyz="-8.8818E-16 -1.9429E-15 -0.018298"
        rpy="0 0 0" />
      <mass
        value="89.513" />
      <inertia
        ixx="3.0398"
        ixy="1.404E-15"
        ixz="4.5781E-16"
        iyy="3.0398"
        iyz="-4.9882E-16"
        izz="5.9277" />
    </inertial>
    <visual>
      <origin
        xyz="0 0 0"
        rpy="0 0 0" />
      <geometry>
        <mesh
          filename="file://${mesh_dir}/Link1.1.STL" />
      </geometry>
      <material
        name="">
        <color
          rgba="0.79216 0.81961 0.93333 1" />
      </material>
    </visual>
    <collision>
    <origin
      xyz="0 0 0"
      rpy="0 0 0" />
      <geometry>
        <cylinder length="0.026" radius="0.370"/>
      </geometry>
    </collision>
  </link>
  <joint
    name="Right_motor_zad"
    type="continuous">
    <origin
      xyz="-0.75 -0.294 0.026645"
      rpy="1.5708 0 0" />
    <parent
      link="Link1" />
    <child
      link="Link1.1" />
    <axis
      xyz="0 0 -1" />
    <mimic
      joint="Caretca_prav_zad_1"
      multiplier="1"
      offset="0" />
  </joint>
  <link
    name="Link1.2">
    <inertial>
      <origin
        xyz="9.2537E-13 -1.1654E-12 -0.11142"
        rpy="0 0 0" />
      <mass
        value="19.264" />
      <inertia
        ixx="0.11226"
        ixy="-1.7113E-19"
        ixz="2.949E-18"
        iyy="0.11226"
        iyz="-1.7687E-18"
        izz="0.038249" />
    </inertial>
    <visual>
      <origin
        xyz="0 0 0"
        rpy="0 0 0" />
      <geometry>
        <mesh
          filename="file://${mesh_dir}/Link1.2.STL" />
      </geometry>
      <material
        name="">
        <color
          rgba="0.6 0.6 0.6 1" />
      </material>
    </visual>
    <collision>
      <origin
        xyz="0 0 0"
        rpy="0 0 0" />
      <geometry>
        <cylinder length="0.191" radius="0.075"/>
      </geometry>
    </collision>
  </link>
  <joint
    name="Caretca_prav_zad_1"
    type="continuous">
    <origin
      xyz="-0.62 -0.261 -0.26836"
      rpy="1.5708 0 0" />
    <parent
      link="Link1" />
    <child
      link="Link1.2" />
    <axis
      xyz="0 0 -1" />
    <mimic
      joint="Caretca_prav_zad_2"
      multiplier="1"
      offset="0" />
  </joint>
  <link
    name="Link1.3">
    <inertial>
      <origin
        xyz="9.2529E-13 1.1651E-12 -0.11142"
        rpy="0 0 0" />
      <mass
        value="19.264" />
      <inertia
        ixx="0.11226"
        ixy="3.4338E-18"
        ixz="2.5554E-18"
        iyy="0.11226"
        iyz="-6.3405E-18"
        izz="0.038249" />
    </inertial>
    <visual>
      <origin
        xyz="0 0 0"
        rpy="0 0 0" />
      <geometry>
        <mesh
          filename="file://${mesh_dir}/Link1.3.STL" />
      </geometry>
      <material
        name="">
        <color
          rgba="0.6 0.6 0.6 1" />
      </material>
    </visual>
    <collision>
      <origin
        xyz="0 0 0"
        rpy="0 0 0" />
      <geometry>
        <cylinder length="0.191" radius="0.075"/>
      </geometry>
    </collision>
  </link>
  <joint
    name="Caretca_prav_zad_2"
    type="continuous">
    <origin
      xyz="-0.18 -0.261 -0.26836"
      rpy="1.5708 0 0" />
    <parent
      link="Link1" />
    <child
      link="Link1.3" />
    <axis
      xyz="0 0 -1" />
    <mimic
      joint="Caretca_prav_pered_1"
      multiplier="1"
      offset="0" />
  </joint>
  <link
    name="Link1.4">
    <inertial>
      <origin
        xyz="-2.4453E-13 3.4951E-13 -0.11142"
        rpy="0 0 0" />
      <mass
        value="19.264" />
      <inertia
        ixx="0.11226"
        ixy="-9.0592E-35"
        ixz="8.6602E-19"
        iyy="0.11226"
        iyz="-7.7691E-18"
        izz="0.038249" />
    </inertial>
    <visual>
      <origin
        xyz="0 0 0"
        rpy="0 0 0" />
      <geometry>
        <mesh
          filename="file://${mesh_dir}/Link1.4.STL" />
      </geometry>
      <material
        name="">
        <color
          rgba="0.6 0.6 0.6 1" />
      </material>
    </visual>
    <collision>
      <origin
        xyz="0 0 0"
        rpy="0 0 0" />
      <geometry>
        <cylinder length="0.191" radius="0.075"/>
      </geometry>
    </collision>
  </link>
  <joint
    name="Caretca_prav_pered_1"
    type="continuous">
    <origin
      xyz="0.17211 -0.261 -0.25777"
      rpy="1.5708 0 0" />
    <parent
      link="Link1" />
    <child
      link="Link1.4" />
    <axis
      xyz="0 0 -1" />
    <mimic
      joint="Caretca_prav_pered_2"
      multiplier="1"
      offset="0" />
  </joint>
  <link
    name="Link1.5">
    <inertial>
      <origin
        xyz="2.6312E-14 2.9463E-14 -0.11142"
        rpy="0 0 0" />
      <mass
        value="19.264" />
      <inertia
        ixx="0.11226"
        ixy="2.6059E-18"
        ixz="1.8622E-19"
        iyy="0.11226"
        iyz="-1.0021E-18"
        izz="0.038249" />
    </inertial>
    <visual>
      <origin
        xyz="0 0 0"
        rpy="0 0 0" />
      <geometry>
        <mesh
          filename="file://${mesh_dir}/Link1.5.STL" />
      </geometry>
      <material
        name="">
        <color
          rgba="0.6 0.6 0.6 1" />
      </material>
    </visual>
    <collision>
      <origin
        xyz="0 0 0"
        rpy="0 0 0" />
      <geometry>
        <cylinder length="0.191" radius="0.075"/>
      </geometry>
    </collision>
  </link>
  <joint
    name="Caretca_prav_pered_2"
    type="continuous">
    <origin
      xyz="0.61132 -0.261 -0.27861"
      rpy="1.5708 0 0" />
    <parent
      link="Link1" />
    <child
      link="Link1.5" />
    <axis
      xyz="0 0 -1" />
    <mimic
      joint="Right_motor_pered"
      multiplier="1"
      offset="0" />
  </joint>
  <link
    name="Link1.6">
    <inertial>
      <origin
        xyz="2.7756E-15 6.7724E-15 -0.018298"
        rpy="0 0 0" />
      <mass
        value="89.513" />
      <inertia
        ixx="3.0398"
        ixy="-2.7576E-16"
        ixz="1.2231E-14"
        iyy="3.0398"
        iyz="-3.2419E-16"
        izz="5.9277" />
    </inertial>
    <visual>
      <origin
        xyz="0 0 0"
        rpy="0 0 0" />
      <geometry>
        <mesh
          filename="file://${mesh_dir}/Link1.6.STL" />
      </geometry>
      <material
        name="">
        <color
          rgba="0.79216 0.81961 0.93333 1" />
      </material>
    </visual>
    <collision>
      <origin
        xyz="0 0 0"
        rpy="0 0 0" />
      <geometry>
        <cylinder length="0.026" radius="0.370"/>
      </geometry>
    </collision>
  </link>
  <joint
    name="Right_motor_pered"
    type="continuous">
    <origin
      xyz="0.75 -0.29399999999998 0.0266448192224933"
      rpy="1.57079632679489 0 0" />
    <parent
      link="Link1" />
    <child
      link="Link1.6" />
    <axis
      xyz="0 0 -1" />
  </joint>
  <link
    name="Link2">
    <inertial>
      <origin
        xyz="1.33947736036602E-08 0.0350748076716151 -0.153693701607068"
        rpy="0 0 0" />
      <mass
        value="50.3713313117347" />
      <inertia
        ixx="0.300716634163792"
        ixy="0.00128531344241592"
        ixz="3.68512180566246E-05"
        iyy="0.508220115739333"
        iyz="1.70676187386356E-08"
        izz="0.246800639065682" />
    </inertial>
    <visual>
      <origin
        xyz="0 0 0"
        rpy="0 0 0" />
      <geometry>
        <mesh
          filename="file://${mesh_dir}/Link2.STL" />
      </geometry>
      <material
        name="">
        <color
          rgba="0.901960784313726 0.92156862745098 0.92156862745098 1" />
      </material>
    </visual>
    <collision>
      <origin
        xyz="0 0 0"
        rpy="0 0 0" />
      <geometry>
        <mesh
          filename="file://${mesh_dir}/Link2.STL" />
      </geometry>
    </collision>
  </link>
  <joint
    name="Left_absorber"
    type="fixed">
    <origin
      xyz="0.0480168574191399 0.304999999999995 -0.229644819222496"
      rpy="0 0 0" />
    <parent
      link="base_link" />
    <child
      link="Link2" />
    <axis
      xyz="0 0 0" />
  </joint>
  <link
    name="Link2.1">
    <inertial>
      <origin
        xyz="0 -2.2204E-16 -0.018298"
        rpy="0 0 0" />
      <mass
        value="89.513" />
      <inertia
        ixx="3.0398"
        ixy="-4.3072E-15"
        ixz="-5.0839E-16"
        iyy="3.0398"
        iyz="7.7875E-16"
        izz="5.9277" />
    </inertial>
    <visual>
      <origin
        xyz="0 0 0"
        rpy="0 0 0" />
      <geometry>
        <mesh
          filename="file://${mesh_dir}/Link2.1.STL" />
      </geometry>
      <material
        name="">
        <color
          rgba="0.79216 0.81961 0.93333 1" />
      </material>
    </visual>
    <collision>
      <origin
        xyz="0 0 0"
        rpy="0 0 0" />
      <geometry>
        <cylinder length="0.026" radius="0.370"/>
      </geometry>
    </collision>
  </link>
  <joint
    name="Left_motor_zad"
    type="continuous">
    <origin
      xyz="-0.75 0.294 0.026645"
      rpy="-1.5708 0 0" />
    <parent
      link="Link2" />
    <child
      link="Link2.1" />
    <axis
      xyz="0 0 1" />
    <mimic
      joint="Caretca_left_zad_1"
      multiplier="1"
      offset="0" />
  </joint>
  <link
    name="Link2.2">
    <inertial>
      <origin
        xyz="-2.0761E-14 2.5285E-14 -0.11142"
        rpy="0 0 0" />
      <mass
        value="19.264" />
      <inertia
        ixx="0.11226"
        ixy="3.8634E-18"
        ixz="3.7671E-18"
        iyy="0.11226"
        iyz="5.4633E-18"
        izz="0.038249" />
    </inertial>
    <visual>
      <origin
        xyz="0 0 0"
        rpy="0 0 0" />
      <geometry>
        <mesh
          filename="file://${mesh_dir}/Link2.2.STL" />
      </geometry>
      <material
        name="">
        <color
          rgba="0.6 0.6 0.6 1" />
      </material>
    </visual>
    <collision>
      <origin
        xyz="0 0 0"
        rpy="0 0 0" />
      <geometry>
        <cylinder length="0.191" radius="0.075"/>
      </geometry>
    </collision>
  </link>
  <joint
    name="Caretca_left_zad_1"
    type="continuous">
    <origin
      xyz="-0.62 0.261 -0.26836"
      rpy="-1.5708 0 0" />
    <parent
      link="Link2" />
    <child
      link="Link2.2" />
    <axis
      xyz="0 0 1" />
    <mimic
      joint="Caretca_left_zad_2"
      multiplier="1"
      offset="0" />
  </joint>
  <link
    name="Link2.3">
    <inertial>
      <origin
        xyz="-2.09277040141842E-14 2.52853293858379E-14 -0.111417882550581"
        rpy="0 0 0" />
      <mass
        value="19.2638793677921" />
      <inertia
        ixx="0.112263770127318"
        ixy="-4.63639140326257E-35"
        ixz="8.66017093368957E-19"
        iyy="0.112263770127318"
        iyz="-4.61512882588658E-18"
        izz="0.0382494488771549" />
    </inertial>
    <visual>
      <origin
        xyz="0 0 0"
        rpy="0 0 0" />
      <geometry>
        <mesh
          filename="file://${mesh_dir}/Link2.3.STL" />
      </geometry>
      <material
        name="">
        <color
          rgba="0.6 0.6 0.6 1" />
      </material>
    </visual>
    <collision>
      <origin
        xyz="0 0 0"
        rpy="0 0 0" />
      <geometry>
        <cylinder length="0.191" radius="0.075"/>
      </geometry>
    </collision>
  </link>
  <joint
    name="Caretca_left_zad_2"
    type="continuous">
    <origin
      xyz="-0.18 0.261 -0.26836"
      rpy="-1.5708 0 0" />
    <parent
      link="Link2" />
    <child
      link="Link2.3" />
    <axis
      xyz="0 0 1" />
    <mimic
      joint="Caretca_left_pered_1"
      multiplier="1"
      offset="0" />
  </joint>
  <link
    name="Link2.4">
    <inertial>
      <origin
        xyz="-1.0214E-14 9.1316E-15 -0.11142"
        rpy="0 0 0" />
      <mass
        value="19.264" />
      <inertia
        ixx="0.11226"
        ixy="3.576E-20"
        ixz="3.6423E-18"
        iyy="0.11226"
        iyz="-1.3812E-18"
        izz="0.038249" />
    </inertial>
    <visual>
      <origin
        xyz="0 0 0"
        rpy="0 0 0" />
      <geometry>
        <mesh
          filename="file://${mesh_dir}/Link2.4.STL" />
      </geometry>
      <material
        name="">
        <color
          rgba="0.6 0.6 0.6 1" />
      </material>
    </visual>
    <collision>
      <origin
        xyz="0 0 0"
        rpy="0 0 0" />
      <geometry>
        <cylinder length="0.191" radius="0.075"/>
      </geometry>
    </collision>
  </link>
  <joint
    name="Caretca_left_pered_1"
    type="continuous">
    <origin
      xyz="0.18 0.261 -0.26836"
      rpy="-1.5708 0 0" />
    <parent
      link="Link2" />
    <child
      link="Link2.4" />
    <axis
      xyz="0 0 1" />
    <mimic
      joint="Caretca_left_pered_2"
      multiplier="1"
      offset="0" />
  </joint>
  <link
    name="Link2.5">
    <inertial>
      <origin
        xyz="-1.2434E-14 -1.8485E-14 -0.11142"
        rpy="0 0 0" />
      <mass
        value="19.264" />
      <inertia
        ixx="0.11226"
        ixy="8.1584E-19"
        ixz="9.8819E-19"
        iyy="0.11226"
        iyz="3.4439E-18"
        izz="0.038249" />
    </inertial>
    <visual>
      <origin
        xyz="0 0 0"
        rpy="0 0 0" />
      <geometry>
        <mesh
          filename="file://${mesh_dir}/Link2.5.STL" />
      </geometry>
      <material
        name="">
        <color
          rgba="0.6 0.6 0.6 1" />
      </material>
    </visual>
    <collision>
      <origin
        xyz="0 0 0"
        rpy="0 0 0" />
      <geometry>
        <cylinder length="0.191" radius="0.075"/>
      </geometry>
    </collision>
  </link>
  <joint
    name="Caretca_left_pered_2"
    type="continuous">
    <origin
      xyz="0.62 0.261 -0.26836"
      rpy="-1.5708 0 0" />
    <parent
      link="Link2" />
    <child
      link="Link2.5" />
    <axis
      xyz="0 0 1" />
    <mimic
      joint="Left_motor_pered"
      multiplier="1"
      offset="0" />
  </joint>
  <link
    name="Link2.6">
    <inertial>
      <origin
        xyz="-6.10622663543836E-15 -1.17683640610267E-14 -0.01829777007936"
        rpy="0 0 0" />
      <mass
        value="89.5129393466618" />
      <inertia
        ixx="3.03984947360915"
        ixy="-1.25243074991317E-15"
        ixz="5.00327111890607E-16"
        iyy="3.03984947360915"
        iyz="5.16740221060823E-16"
        izz="5.92768576051744" />
    </inertial>
    <visual>
      <origin
        xyz="0 0 0"
        rpy="0 0 0" />
      <geometry>
        <mesh
          filename="file://${mesh_dir}/Link2.6.STL" />
      </geometry>
      <material
        name="">
        <color
          rgba="0.792156862745098 0.819607843137255 0.933333333333333 1" />
      </material>
    </visual>
    <collision>
      <origin
        xyz="0 0 0"
        rpy="0 0 0" />
      <geometry>
        <cylinder length="0.026" radius="0.370"/>
      </geometry>
    </collision>
  </link>
  <joint
    name="Left_motor_pered"
    type="continuous">
    <origin
      xyz="0.750000000000002 0.294 0.026644819222494"
      rpy="-1.5707963267949 0 0" />
    <parent
      link="Link2" />
    <child
      link="Link2.6" />
    <axis
      xyz="0 0 1" />
  </joint>
</robot>